2023-11-15 18:24:14 | ERROR | PacienteService.editar_paciente() got an unexpected keyword argument 'id_usuario_crea'
2023-11-15 18:24:14 | ERROR | Traceback (most recent call last):
  File "C:\Users\lopez\OneDrive\Documentos\Python-Workspace\med_manager_CSL_api\src\routes\PacientesRoutes.py", line 104, in route_editar_paciente
    resultado = PacienteService.editar_paciente(
                ^^^^^^^^^^^^^^^^^^^^^^^^^^^^^^^^
TypeError: PacienteService.editar_paciente() got an unexpected keyword argument 'id_usuario_crea'

2023-11-15 18:24:44 | ERROR | name 'id_paciente' is not defined
2023-11-15 18:25:03 | ERROR | (1054, "Unknown column 'idUsuarioModifica' in 'field list'")
2023-11-15 18:26:10 | ERROR | (1054, "Unknown column 'fechaModificacion' in 'field list'")
2023-11-15 18:26:22 | ERROR | (1054, "Unknown column 'fechaModificacion' in 'field list'")
